Workbook

Sheet Phiếu nhập
A1: =[1]ThongtinDN!B5&" "&[1]ThongtinDN!C5 -> Tên đơn vị: CÔNG TY TNHH JOY WORLD ENTERTAINMENT
A2: =[1]ThongtinDN!B6&" "&[1]ThongtinDN!C6 -> Địa chỉ: 154A Đường Nguyễn Thị Thập, Phường Tân Thuận, Tp.HCM
A3: =[1]ThongtinDN!B7&" "&[1]ThongtinDN!C7 -> MST: 0318958531
A6: PHIẾU NHẬP KHO | F6: Nợ TK: | G6: =IF($C8="","",VLOOKUP($C$8,[1]Nhập!$A$11:$O$19999,8,0)) -> 0
B7: Ngày 12 tháng 11 năm 2025 | F7: Có TK: | G7: =IF($C8="","",VLOOKUP($C$8,[1]Nhập!$A$11:$O$19999,9,0)) -> 0
B8: Số: | C8: PN001/12.25
A9: ="Nhập Theo Hóa Đơn số :"&" "&IF($C$8="","",TEXT(VLOOKUP($C$8,[1]Nhập!$A$11:$O$19999,2,0),"0000000"))&" "&B7 -> Nhập Theo Hóa Đơn số : 0000205 Ngày 12 tháng 11 năm 2025
A10: ="Của :"&IF($C$8="","",VLOOKUP($C$8,[1]Nhập!$A$11:$O$19999,5,0))&" "&"Mã số thuế : "&IF($C$8=""," ",VLOOKUP($C$8,[1]Nhập!$A$11:$O$19999,7,0)) -> Của : Mã số thuế :
A11: ="Địa chỉ: "&IF($C$8="","",VLOOKUP($C$8,[1]Nhập!$A$11:$O$19999,6,0)) -> Địa chỉ:
A12: ="Nhập tại kho : "&[1]ThongtinDN!C5 -> Nhập tại kho : CÔNG TY TNHH JOY WORLD ENTERTAINMENT
A13: STT | B13: Tên nhãn hiệu,qui cách, phẩm chất vật tư (sản phẩm,hàng hoá) | C13: Mã Vật Tư | D13: Đơn vị tính | E13: Số lượng | G13: Đơn giá | H13: Thành tiền | I13: Ghi chú
E14: Theo chúng từ | F14: Thực Nhập
A15: A | B15: B | C15: C | D15: D | E15: 1 | F15: 2 | G15: 3 | H15: 4
A16: =IF(B16="","",COUNTA($B$16:B16)) -> 1 | B16: {=IF($I16="","",INDEX([1]Nhập!$K$11:$K$19999,$I16))} -> Nhãn dán Công viên giải trí | C16: {=IF($I16="","",INDEX([1]Nhập!$J$11:$J$19999,$I16))} -> JWG0001 | D16: {=IF($I16="","",INDEX([1]Nhập!$L$11:$L$19999,$I16))} -> Cái | E16: {=IF($I16="","",INDEX([1]Nhập!$M$11:$M$19999,$I16))} -> 2800 | F16: =E16 -> 2800 | G16: {=IF($I16="","",INDEX([1]Nhập!$N$11:$N$19999,$I16))} -> 2142.6615 | H16: {=IF($I16="","",INDEX([1]Nhập!$O$11:$O$19999,$I16))} -> 5999452.2 | I16: =IF(TYPE(MATCH($C$8,[1]Nhập!$A$11:$A$20000,0))=16,"",MATCH($C$8,[1]Nhập!$A$11:$A$20000,0)) -> 1
A17: =IF(B17="","",COUNTA($B$16:B17)) -> 2 | B17: {=IF($I17="","",INDEX([1]Nhập!$K$11:$K$19999,$I17))} -> Đồng xu kỷ niệm độc quyền B.Duck | C17: {=IF($I17="","",INDEX([1]Nhập!$J$11:$J$19999,$I17))} -> JWG0002 | D17: {=IF($I17="","",INDEX([1]Nhập!$L$11:$L$19999,$I17))} -> Cái | E17: {=IF($I17="","",INDEX([1]Nhập!$M$11:$M$19999,$I17))} -> 1500 | F17: =E17 -> 1500 | G17: {=IF($I17="","",INDEX([1]Nhập!$N$11:$N$19999,$I17))} -> 9258.5115 | H17: {=IF($I17="","",INDEX([1]Nhập!$O$11:$O$19999,$I17))} -> 13887767 | I17: =IF(TYPE(MATCH($C$8,OFFSET([1]Nhập!$A$11,I16,0):'[1]Nhập'!$A$20000,0)+I16)=16,"",MATCH($C$8,OFFSET([1]Nhập!$A$11,I16,0):'[1]Nhập'!$A$20000,0)+I16) -> 2
A18: =IF(B18="","",COUNTA($B$16:B18)) -> 3 | B18: {=IF($I18="","",INDEX([1]Nhập!$K$11:$K$19999,$I18))} -> Hộp đựng đồng xu kỷ niệm | C18: {=IF($I18="","",INDEX([1]Nhập!$J$11:$J$19999,$I18))} -> JWG0003 | D18: {=IF($I18="","",INDEX([1]Nhập!$L$11:$L$19999,$I18))} -> Cái | E18: {=IF($I18="","",INDEX([1]Nhập!$M$11:$M$19999,$I18))} -> 1500 | F18: =E18 -> 1500 | G18: {=IF($I18="","",INDEX([1]Nhập!$N$11:$N$19999,$I18))} -> 9258.5115 | H18: {=IF($I18="","",INDEX([1]Nhập!$O$11:$O$19999,$I18))} -> 13887767 | I18: =IF(TYPE(MATCH($C$8,OFFSET([1]Nhập!$A$11,I17,0):'[1]Nhập'!$A$20000,0)+I17)=16,"",MATCH($C$8,OFFSET([1]Nhập!$A$11,I17,0):'[1]Nhập'!$A$20000,0)+I17) -> 3
A19: =IF(B19="","",COUNTA($B$16:B19)) -> 4 | B19: {=IF($I19="","",INDEX([1]Nhập!$K$11:$K$19999,$I19))} -> Thẻ đánh dấu sách độc quyền | C19: {=IF($I19="","",INDEX([1]Nhập!$J$11:$J$19999,$I19))} -> JWG0004 | D19: {=IF($I19="","",INDEX([1]Nhập!$L$11:$L$19999,$I19))} -> Cái | E19: {=IF($I19="","",INDEX([1]Nhập!$M$11:$M$19999,$I19))} -> 2000 | F19: =E19 -> 2000 | G19: {=IF($I19="","",INDEX([1]Nhập!$N$11:$N$19999,$I19))} -> 740.5755 | H19: {=IF($I19="","",INDEX([1]Nhập!$O$11:$O$19999,$I19))} -> 1481151 | I19: =IF(TYPE(MATCH($C$8,OFFSET([1]Nhập!$A$11,I18,0):'[1]Nhập'!$A$20000,0)+I18)=16,"",MATCH($C$8,OFFSET([1]Nhập!$A$11,I18,0):'[1]Nhập'!$A$20000,0)+I18) -> 4
A20: =IF(B20="","",COUNTA($B$16:B20)) -> 5 | B20: {=IF($I20="","",INDEX([1]Nhập!$K$11:$K$19999,$I20))} -> Nam châm tủ lạnh độc quyền B.Duck | C20: {=IF($I20="","",INDEX([1]Nhập!$J$11:$J$19999,$I20))} -> JWG0005 | D20: {=IF($I20="","",INDEX([1]Nhập!$L$11:$L$19999,$I20))} -> Cái | E20: {=IF($I20="","",INDEX([1]Nhập!$M$11:$M$19999,$I20))} -> 1500 | F20: =E20 -> 1500 | G20: {=IF($I20="","",INDEX([1]Nhập!$N$11:$N$19999,$I20))} -> 8146.3305 | H20: {=IF($I20="","",INDEX([1]Nhập!$O$11:$O$19999,$I20))} -> 12219496 | I20: =IF(TYPE(MATCH($C$8,OFFSET([1]Nhập!$A$11,I19,0):'[1]Nhập'!$A$20000,0)+I19)=16,"",MATCH($C$8,OFFSET([1]Nhập!$A$11,I19,0):'[1]Nhập'!$A$20000,0)+I19) -> 5
A21: =IF(B21="","",COUNTA($B$16:B21)) -> 6 | B21: {=IF($I21="","",INDEX([1]Nhập!$K$11:$K$19999,$I21))} -> Bong bóng cài tóc / Băng đô bong bóng | C21: {=IF($I21="","",INDEX([1]Nhập!$J$11:$J$19999,$I21))} -> JWG0006 | D21: {=IF($I21="","",INDEX([1]Nhập!$L$11:$L$19999,$I21))} -> Cái | E21: {=IF($I21="","",INDEX([1]Nhập!$M$11:$M$19999,$I21))} -> 3000 | F21: =E21 -> 3000 | G21: {=IF($I21="","",INDEX([1]Nhập!$N$11:$N$19999,$I21))} -> 1112.181 | H21: {=IF($I21="","",INDEX([1]Nhập!$O$11:$O$19999,$I21))} -> 3336543 | I21: =IF(TYPE(MATCH($C$8,OFFSET([1]Nhập!$A$11,I20,0):'[1]Nhập'!$A$20000,0)+I20)=16,"",MATCH($C$8,OFFSET([1]Nhập!$A$11,I20,0):'[1]Nhập'!$A$20000,0)+I20) -> 6
A22: =IF(B22="","",COUNTA($B$16:B22)) -> 7 | B22: {=IF($I22="","",INDEX([1]Nhập!$K$11:$K$19999,$I22))} -> Bong bóng ba lô | C22: {=IF($I22="","",INDEX([1]Nhập!$J$11:$J$19999,$I22))} -> JWG0007 | D22: {=IF($I22="","",INDEX([1]Nhập!$L$11:$L$19999,$I22))} -> Cái | E22: {=IF($I22="","",INDEX([1]Nhập!$M$11:$M$19999,$I22))} -> 4000 | F22: =E22 -> 4000 | G22: {=IF($I22="","",INDEX([1]Nhập!$N$11:$N$19999,$I22))} -> 1665.636 | H22: {=IF($I22="","",INDEX([1]Nhập!$O$11:$O$19999,$I22))} -> 6662544 | I22: =IF(TYPE(MATCH($C$8,OFFSET([1]Nhập!$A$11,I21,0):'[1]Nhập'!$A$20000,0)+I21)=16,"",MATCH($C$8,OFFSET([1]Nhập!$A$11,I21,0):'[1]Nhập'!$A$20000,0)+I21) -> 7
A23: =IF(B23="","",COUNTA($B$16:B23)) -> 8 | B23: {=IF($I23="","",INDEX([1]Nhập!$K$11:$K$19999,$I23))} -> Huy hiệu thiếc B.Duck | C23: {=IF($I23="","",INDEX([1]Nhập!$J$11:$J$19999,$I23))} -> JWG0008 | D23: {=IF($I23="","",INDEX([1]Nhập!$L$11:$L$19999,$I23))} -> Cái | E23: {=IF($I23="","",INDEX([1]Nhập!$M$11:$M$19999,$I23))} -> 2000 | F23: =E23 -> 2000 | G23: {=IF($I23="","",INDEX([1]Nhập!$N$11:$N$19999,$I23))} -> 1852.7565 | H23: {=IF($I23="","",INDEX([1]Nhập!$O$11:$O$19999,$I23))} -> 3705513 | I23: =IF(TYPE(MATCH($C$8,OFFSET([1]Nhập!$A$11,I22,0):'[1]Nhập'!$A$20000,0)+I22)=16,"",MATCH($C$8,OFFSET([1]Nhập!$A$11,I22,0):'[1]Nhập'!$A$20000,0)+I22) -> 8
A24: =IF(B24="","",COUNTA($B$16:B24)) -> 9 | B24: {=IF($I24="","",INDEX([1]Nhập!$K$11:$K$19999,$I24))} -> Sổ tay (kiểu Hộ chiếu) | C24: {=IF($I24="","",INDEX([1]Nhập!$J$11:$J$19999,$I24))} -> JWG0009 | D24: {=IF($I24="","",INDEX([1]Nhập!$L$11:$L$19999,$I24))} -> Cái | E24: {=IF($I24="","",INDEX([1]Nhập!$M$11:$M$19999,$I24))} -> 8000 | F24: =E24 -> 8000 | G24: {=IF($I24="","",INDEX([1]Nhập!$N$11:$N$19999,$I24))} -> 1296.666 | H24: {=IF($I24="","",INDEX([1]Nhập!$O$11:$O$19999,$I24))} -> 10373328 | I24: =IF(TYPE(MATCH($C$8,OFFSET([1]Nhập!$A$11,I23,0):'[1]Nhập'!$A$20000,0)+I23)=16,"",MATCH($C$8,OFFSET([1]Nhập!$A$11,I23,0):'[1]Nhập'!$A$20000,0)+I23) -> 9
A25: =IF(B25="","",COUNTA($B$16:B25)) -> 10 | B25: {=IF($I25="","",INDEX([1]Nhập!$K$11:$K$19999,$I25))} -> Huy hiệu hợp kim kẽm | C25: {=IF($I25="","",INDEX([1]Nhập!$J$11:$J$19999,$I25))} -> JWG0010 | D25: {=IF($I25="","",INDEX([1]Nhập!$L$11:$L$19999,$I25))} -> Cái | E25: {=IF($I25="","",INDEX([1]Nhập!$M$11:$M$19999,$I25))} -> 1500 | F25: =E25 -> 1500 | G25: {=IF($I25="","",INDEX([1]Nhập!$N$11:$N$19999,$I25))} -> 9258.5115 | H25: {=IF($I25="","",INDEX([1]Nhập!$O$11:$O$19999,$I25))} -> 13887767 | I25: =IF(TYPE(MATCH($C$8,OFFSET([1]Nhập!$A$11,I24,0):'[1]Nhập'!$A$20000,0)+I24)=16,"",MATCH($C$8,OFFSET([1]Nhập!$A$11,I24,0):'[1]Nhập'!$A$20000,0)+I24) -> 10
A26: =IF(B26="","",COUNTA($B$16:B26)) -> 11 | B26: {=IF($I26="","",INDEX([1]Nhập!$K$11:$K$19999,$I26))} -> Vịt lăn chạy bằng quán tính | C26: {=IF($I26="","",INDEX([1]Nhập!$J$11:$J$19999,$I26))} -> JWG0011 | D26: {=IF($I26="","",INDEX([1]Nhập!$L$11:$L$19999,$I26))} -> Cái | E26: {=IF($I26="","",INDEX([1]Nhập!$M$11:$M$19999,$I26))} -> 720 | F26: =E26 -> 720 | G26: {=IF($I26="","",INDEX([1]Nhập!$N$11:$N$19999,$I26))} -> 9258.5115 | H26: {=IF($I26="","",INDEX([1]Nhập!$O$11:$O$19999,$I26))} -> 6666128.3 | I26: =IF(TYPE(MATCH($C$8,OFFSET([1]Nhập!$A$11,I25,0):'[1]Nhập'!$A$20000,0)+I25)=16,"",MATCH($C$8,OFFSET([1]Nhập!$A$11,I25,0):'[1]Nhập'!$A$20000,0)+I25) -> 11
A27: =IF(B27="","",COUNTA($B$16:B27)) -> 12 | B27: {=IF($I27="","",INDEX([1]Nhập!$K$11:$K$19999,$I27))} -> Thú bông trang trí treo gương | C27: {=IF($I27="","",INDEX([1]Nhập!$J$11:$J$19999,$I27))} -> JWG0012 | D27: {=IF($I27="","",INDEX([1]Nhập!$L$11:$L$19999,$I27))} -> Cái | E27: {=IF($I27="","",INDEX([1]Nhập!$M$11:$M$19999,$I27))} -> 146 | F27: =E27 -> 146 | G27: {=IF($I27="","",INDEX([1]Nhập!$N$11:$N$19999,$I27))} -> 14811.51 | H27: {=IF($I27="","",INDEX([1]Nhập!$O$11:$O$19999,$I27))} -> 2162480.5 | I27: =IF(TYPE(MATCH($C$8,OFFSET([1]Nhập!$A$11,I26,0):'[1]Nhập'!$A$20000,0)+I26)=16,"",MATCH($C$8,OFFSET([1]Nhập!$A$11,I26,0):'[1]Nhập'!$A$20000,0)+I26) -> 12
A28: =IF(B28="","",COUNTA($B$16:B28)) -> 13 | B28: {=IF($I28="","",INDEX([1]Nhập!$K$11:$K$19999,$I28))} -> Ván trượt 17 inch | C28: {=IF($I28="","",INDEX([1]Nhập!$J$11:$J$19999,$I28))} -> JWG0013 | D28: {=IF($I28="","",INDEX([1]Nhập!$L$11:$L$19999,$I28))} -> Cái | E28: {=IF($I28="","",INDEX([1]Nhập!$M$11:$M$19999,$I28))} -> 144 | F28: =E28 -> 144 | G28: {=IF($I28="","",INDEX([1]Nhập!$N$11:$N$19999,$I28))} -> 20367.144 | H28: {=IF($I28="","",INDEX([1]Nhập!$O$11:$O$19999,$I28))} -> 2932868.7 | I28: =IF(TYPE(MATCH($C$8,OFFSET([1]Nhập!$A$11,I27,0):'[1]Nhập'!$A$20000,0)+I27)=16,"",MATCH($C$8,OFFSET([1]Nhập!$A$11,I27,0):'[1]Nhập'!$A$20000,0)+I27) -> 13
... A45: =IF(B45="","",COUNTA($B$16:B45)) -> 30 | B45: {=IF($I45="","",INDEX([1]Nhập!$K$11:$K$19999,$I45))} -> Que thổi bong bóng kẹo ngọt | C45: {=IF($I45="","",INDEX([1]Nhập!$J$11:$J$19999,$I45))} -> JWG0030 | D45: {=IF($I45="","",INDEX([1]Nhập!$L$11:$L$19999,$I45))} -> Cái | E45: {=IF($I45="","",INDEX([1]Nhập!$M$11:$M$19999,$I45))} -> 288 | F45: =E45 -> 288 | G45: {=IF($I45="","",INDEX([1]Nhập!$N$11:$N$19999,$I45))} -> 1852.7565 | H45: {=IF($I45="","",INDEX([1]Nhập!$O$11:$O$19999,$I45))} -> 533593.87 | I45: =IF(TYPE(MATCH($C$8,OFFSET([1]Nhập!$A$11,I44,0):'[1]Nhập'!$A$20000,0)+I44)=16,"",MATCH($C$8,OFFSET([1]Nhập!$A$11,I44,0):'[1]Nhập'!$A$20000,0)+I44) -> 30
A46: =IF(B46="","",COUNTA($B$16:B46)) -> 31 | B46: {=IF($I46="","",INDEX([1]Nhập!$K$11:$K$19999,$I46))} -> Vịt vàng huýt sáo | C46: =IF($I46="","",INDEX([1]Nhập!$J$11:$J$19999,$I46)) -> JWG0031 | D46: {=IF($I46="","",INDEX([1]Nhập!$L$11:$L$19999,$I46))} -> Cái | E46: {=IF($I46="","",INDEX([1]Nhập!$M$11:$M$19999,$I46))} -> 320 | F46: =E46 -> 320 | G46: {=IF($I46="","",INDEX([1]Nhập!$N$11:$N$19999,$I46))} -> 1852.7565 | H46: {=IF($I46="","",INDEX([1]Nhập!$O$11:$O$19999,$I46))} -> 592882.08 | I46: =IF(TYPE(MATCH($C$8,OFFSET([1]Nhập!$A$11,I45,0):'[1]Nhập'!$A$20000,0)+I45)=16,"",MATCH($C$8,OFFSET([1]Nhập!$A$11,I45,0):'[1]Nhập'!$A$20000,0)+I45) -> 31
A47: =IF(B47="","",COUNTA($B$16:B47)) -> 32 | B47: {=IF($I47="","",INDEX([1]Nhập!$K$11:$K$19999,$I47))} -> Đồ treo xe hơi B. Duck chính hãng series Buffy Friends - Kiểu Thỏ con | C47: {=IF($I47="","",INDEX([1]Nhập!$J$11:$J$19999,$I47))} -> JWG0032 | D47: {=IF($I47="","",INDEX([1]Nhập!$L$11:$L$19999,$I47))} -> Cái | E47: {=IF($I47="","",INDEX([1]Nhập!$M$11:$M$19999,$I47))} -> 100 | F47: =E47 -> 100 | G47: {=IF($I47="","",INDEX([1]Nhập!$N$11:$N$19999,$I47))} -> 2962.302 | H47: {=IF($I47="","",INDEX([1]Nhập!$O$11:$O$19999,$I47))} -> 296230.2 | I47: =IF(TYPE(MATCH($C$8,OFFSET([1]Nhập!$A$11,I46,0):'[1]Nhập'!$A$20000,0)+I46)=16,"",MATCH($C$8,OFFSET([1]Nhập!$A$11,I46,0):'[1]Nhập'!$A$20000,0)+I46) -> 32
A48: =IF(B48="","",COUNTA($B$16:B48)) -> 33 | B48: {=IF($I48="","",INDEX([1]Nhập!$K$11:$K$19999,$I48))} -> Đồ treo xe hơi B. Duck chính hãng series Buffy Friends - Kiểu Gấu con | C48: {=IF($I48="","",INDEX([1]Nhập!$J$11:$J$19999,$I48))} -> JWG0033 | D48: {=IF($I48="","",INDEX([1]Nhập!$L$11:$L$19999,$I48))} -> Cái | E48: {=IF($I48="","",INDEX([1]Nhập!$M$11:$M$19999,$I48))} -> 100 | F48: =E48 -> 100 | G48: {=IF($I48="","",INDEX([1]Nhập!$N$11:$N$19999,$I48))} -> 2962.302 | H48: {=IF($I48="","",INDEX([1]Nhập!$O$11:$O$19999,$I48))} -> 296230.2 | I48: =IF(TYPE(MATCH($C$8,OFFSET([1]Nhập!$A$11,I47,0):'[1]Nhập'!$A$20000,0)+I47)=16,"",MATCH($C$8,OFFSET([1]Nhập!$A$11,I47,0):'[1]Nhập'!$A$20000,0)+I47) -> 33
A49: =IF(B49="","",COUNTA($B$16:B49)) -> 34 | B49: {=IF($I49="","",INDEX([1]Nhập!$K$11:$K$19999,$I49))} -> Trò Chơi Cờ Vua Bốn Trong Một | C49: {=IF($I49="","",INDEX([1]Nhập!$J$11:$J$19999,$I49))} -> JWG0034 | D49: {=IF($I49="","",INDEX([1]Nhập!$L$11:$L$19999,$I49))} -> Cái | E49: {=IF($I49="","",INDEX([1]Nhập!$M$11:$M$19999,$I49))} -> 96 | F49: =E49 -> 96 | G49: {=IF($I49="","",INDEX([1]Nhập!$N$11:$N$19999,$I49))} -> 5555.634 | H49: {=IF($I49="","",INDEX([1]Nhập!$O$11:$O$19999,$I49))} -> 533340.86 | I49: =IF(TYPE(MATCH($C$8,OFFSET([1]Nhập!$A$11,I48,0):'[1]Nhập'!$A$20000,0)+I48)=16,"",MATCH($C$8,OFFSET([1]Nhập!$A$11,I48,0):'[1]Nhập'!$A$20000,0)+I48) -> 34
A50: =IF(B50="","",COUNTA($B$16:B50)) -> 35 | B50: {=IF($I50="","",INDEX([1]Nhập!$K$11:$K$19999,$I50))} -> Đồ treo xe hơi B. Duck chính hãng series Buffy Friends - Phiên bản Gấu trúc | C50: {=IF($I50="","",INDEX([1]Nhập!$J$11:$J$19999,$I50))} -> JWG0035 | D50: {=IF($I50="","",INDEX([1]Nhập!$L$11:$L$19999,$I50))} -> Cái | E50: {=IF($I50="","",INDEX([1]Nhập!$M$11:$M$19999,$I50))} -> 100 | F50: =E50 -> 100 | G50: {=IF($I50="","",INDEX([1]Nhập!$N$11:$N$19999,$I50))} -> 3702.8775 | H50: {=IF($I50="","",INDEX([1]Nhập!$O$11:$O$19999,$I50))} -> 370287.75 | I50: =IF(TYPE(MATCH($C$8,OFFSET([1]Nhập!$A$11,I49,0):'[1]Nhập'!$A$20000,0)+I49)=16,"",MATCH($C$8,OFFSET([1]Nhập!$A$11,I49,0):'[1]Nhập'!$A$20000,0)+I49) -> 35
A51: =IF(B51="","",COUNTA($B$16:B51)) -> 36 | B51: {=IF($I51="","",INDEX([1]Nhập!$K$11:$K$19999,$I51))} -> Súng nước thuyền kayak chuối | C51: {=IF($I51="","",INDEX([1]Nhập!$J$11:$J$19999,$I51))} -> JWG0036 | D51: {=IF($I51="","",INDEX([1]Nhập!$L$11:$L$19999,$I51))} -> Cái | E51: {=IF($I51="","",INDEX([1]Nhập!$M$11:$M$19999,$I51))} -> 432 | F51: =E51 -> 432 | G51: {=IF($I51="","",INDEX([1]Nhập!$N$11:$N$19999,$I51))} -> 1852.7565 | H51: {=IF($I51="","",INDEX([1]Nhập!$O$11:$O$19999,$I51))} -> 800390.81 | I51: =IF(TYPE(MATCH($C$8,OFFSET([1]Nhập!$A$11,I50,0):'[1]Nhập'!$A$20000,0)+I50)=16,"",MATCH($C$8,OFFSET([1]Nhập!$A$11,I50,0):'[1]Nhập'!$A$20000,0)+I50) -> 36
A52: =IF(B52="","",COUNTA($B$16:B52)) -> 37 | B52: {=IF($I52="","",INDEX([1]Nhập!$K$11:$K$19999,$I52))} -> Đồng hồ điện tử chiếu hình | C52: {=IF($I52="","",INDEX([1]Nhập!$J$11:$J$19999,$I52))} -> JWG0037 | D52: {=IF($I52="","",INDEX([1]Nhập!$L$11:$L$19999,$I52))} -> Cái | E52: {=IF($I52="","",INDEX([1]Nhập!$M$11:$M$19999,$I52))} -> 100 | F52: =E52 -> 100 | G52: {=IF($I52="","",INDEX([1]Nhập!$N$11:$N$19999,$I52))} -> 2962.302 | H52: {=IF($I52="","",INDEX([1]Nhập!$O$11:$O$19999,$I52))} -> 296230.2 | I52: =IF(TYPE(MATCH($C$8,OFFSET([1]Nhập!$A$11,I51,0):'[1]Nhập'!$A$20000,0)+I51)=16,"",MATCH($C$8,OFFSET([1]Nhập!$A$11,I51,0):'[1]Nhập'!$A$20000,0)+I51) -> 37
A53: =IF(B53="","",COUNTA($B$16:B53)) -> 38 | B53: {=IF($I53="","",INDEX([1]Nhập!$K$11:$K$19999,$I53))} -> Đồ treo xe hơi B. Duck chính hãng series Buffy Friends - Phiên bản Tàu hỏa | C53: {=IF($I53="","",INDEX([1]Nhập!$J$11:$J$19999,$I53))} -> JWG0038 | D53: {=IF($I53="","",INDEX([1]Nhập!$L$11:$L$19999,$I53))} -> Cái | E53: {=IF($I53="","",INDEX([1]Nhập!$M$11:$M$19999,$I53))} -> 100 | F53: =E53 -> 100 | G53: {=IF($I53="","",INDEX([1]Nhập!$N$11:$N$19999,$I53))} -> 2962.302 | H53: {=IF($I53="","",INDEX([1]Nhập!$O$11:$O$19999,$I53))} -> 296230.2 | I53: =IF(TYPE(MATCH($C$8,OFFSET([1]Nhập!$A$11,I52,0):'[1]Nhập'!$A$20000,0)+I52)=16,"",MATCH($C$8,OFFSET([1]Nhập!$A$11,I52,0):'[1]Nhập'!$A$20000,0)+I52) -> 38
A54: =IF(B54="","",COUNTA($B$16:B54)) -> 39 | B54: {=IF($I54="","",INDEX([1]Nhập!$K$11:$K$19999,$I54))} -> Trò chơi cờ 2 trong 1 | C54: {=IF($I54="","",INDEX([1]Nhập!$J$11:$J$19999,$I54))} -> JWG0039 | D54: {=IF($I54="","",INDEX([1]Nhập!$L$11:$L$19999,$I54))} -> Cái | E54: {=IF($I54="","",INDEX([1]Nhập!$M$11:$M$19999,$I54))} -> 192 | F54: =E54 -> 192 | G54: {=IF($I54="","",INDEX([1]Nhập!$N$11:$N$19999,$I54))} -> 3702.8775 | H54: {=IF($I54="","",INDEX([1]Nhập!$O$11:$O$19999,$I54))} -> 710952.48 | I54: =IF(TYPE(MATCH($C$8,OFFSET([1]Nhập!$A$11,I53,0):'[1]Nhập'!$A$20000,0)+I53)=16,"",MATCH($C$8,OFFSET([1]Nhập!$A$11,I53,0):'[1]Nhập'!$A$20000,0)+I53) -> 39
A55: =IF(B55="","",COUNTA($B$16:B55)) -> 40 | B55: {=IF($I55="","",INDEX([1]Nhập!$K$11:$K$19999,$I55))} -> Đồ treo xe hơi B. Duck chính hãng series Buffy Friends - Kiểu Ếch | C55: {=IF($I55="","",INDEX([1]Nhập!$J$11:$J$19999,$I55))} -> JWG0040 | D55: {=IF($I55="","",INDEX([1]Nhập!$L$11:$L$19999,$I55))} -> Cái | E55: {=IF($I55="","",INDEX([1]Nhập!$M$11:$M$19999,$I55))} -> 100 | F55: =E55 -> 100 | G55: {=IF($I55="","",INDEX([1]Nhập!$N$11:$N$19999,$I55))} -> 2962.302 | H55: {=IF($I55="","",INDEX([1]Nhập!$O$11:$O$19999,$I55))} -> 296230.2 | I55: =IF(TYPE(MATCH($C$8,OFFSET([1]Nhập!$A$11,I54,0):'[1]Nhập'!$A$20000,0)+I54)=16,"",MATCH($C$8,OFFSET([1]Nhập!$A$11,I54,0):'[1]Nhập'!$A$20000,0)+I54) -> 40
A56: =IF(B56="","",COUNTA($B$16:B56)) -> 41 | B56: {=IF($I56="","",INDEX([1]Nhập!$K$11:$K$19999,$I56))} -> B. Duck chính hãng series Họa sĩ Vịt Vàng - Bút chì sáp | C56: {=IF($I56="","",INDEX([1]Nhập!$J$11:$J$19999,$I56))} -> JWG0041 | D56: {=IF($I56="","",INDEX([1]Nhập!$L$11:$L$19999,$I56))} -> Cái | E56: {=IF($I56="","",INDEX([1]Nhập!$M$11:$M$19999,$I56))} -> 100 | F56: =E56 -> 100 | G56: {=IF($I56="","",INDEX([1]Nhập!$N$11:$N$19999,$I56))} -> 2962.302 | H56: {=IF($I56="","",INDEX([1]Nhập!$O$11:$O$19999,$I56))} -> 296230.2 | I56: =IF(TYPE(MATCH($C$8,OFFSET([1]Nhập!$A$11,I55,0):'[1]Nhập'!$A$20000,0)+I55)=16,"",MATCH($C$8,OFFSET([1]Nhập!$A$11,I55,0):'[1]Nhập'!$A$20000,0)+I55) -> 41
A57: =IF(B57="","",COUNTA($B$16:B57)) -> 42 | B57: {=IF($I57="","",INDEX([1]Nhập!$K$11:$K$19999,$I57))} -> Mặt dây chuyền móc khóa B. Duck | C57: {=IF($I57="","",INDEX([1]Nhập!$J$11:$J$19999,$I57))} -> JWG0042 | D57: {=IF($I57="","",INDEX([1]Nhập!$L$11:$L$19999,$I57))} -> Cái | E57: {=IF($I57="","",INDEX([1]Nhập!$M$11:$M$19999,$I57))} -> 100 | F57: =E57 -> 100 | G57: {=IF($I57="","",INDEX([1]Nhập!$N$11:$N$19999,$I57))} -> 2962.302 | H57: {=IF($I57="","",INDEX([1]Nhập!$O$11:$O$19999,$I57))} -> 296230.2 | I57: =IF(TYPE(MATCH($C$8,OFFSET([1]Nhập!$A$11,I56,0):'[1]Nhập'!$A$20000,0)+I56)=16,"",MATCH($C$8,OFFSET([1]Nhập!$A$11,I56,0):'[1]Nhập'!$A$20000,0)+I56) -> 42
A58: =IF(B58="","",COUNTA($B$16:B58)) -> 43 | B58: {=IF($I58="","",INDEX([1]Nhập!$K$11:$K$19999,$I58))} -> Mặt dây chuyền B. Duck chính hãng kiểu khắc gỗ - Vịt Nằm Kiếm Tiền (Lying Down to Make Money) | C58: {=IF($I58="","",INDEX([1]Nhập!$J$11:$J$19999,$I58))} -> JWG0043 | D58: {=IF($I58="","",INDEX([1]Nhập!$L$11:$L$19999,$I58))} -> Cái | E58: {=IF($I58="","",INDEX([1]Nhập!$M$11:$M$19999,$I58))} -> 100 | F58: =E58 -> 100 | G58: {=IF($I58="","",INDEX([1]Nhập!$N$11:$N$19999,$I58))} -> 2962.302 | H58: {=IF($I58="","",INDEX([1]Nhập!$O$11:$O$19999,$I58))} -> 296230.2 | I58: =IF(TYPE(MATCH($C$8,OFFSET([1]Nhập!$A$11,I57,0):'[1]Nhập'!$A$20000,0)+I57)=16,"",MATCH($C$8,OFFSET([1]Nhập!$A$11,I57,0):'[1]Nhập'!$A$20000,0)+I57) -> 43
...
